<?xml version="1.0"?>
<robot name="romeoH37">
    <link name="AccelerometerHead" />
    <link name="Head" />
    <link name="Torso_link">
        <inertial>
            <mass value="9.9216" />
            <origin xyz="0.0023 0 -0.04854" rpy="0 -0 0" />
            <inertia ixx="0.105956" ixy="-0.000359651" ixz="0.00173121" iyy="0.103402" iyz="-0.00200843" izz="0.110575" />
        </inertial>
        <visual>
            <origin xyz="0 0 0" rpy="0 -0 0" />
            <geometry>
                <mesh filename="file:///home/sbarthelemy/ar/a/simulation/alrobotmodel/libalmodelutils/share/alrobotmodel/meshes/romeo/Torso.dae" scale="1 1 1" />
            </geometry>
        </visual>
    </link>
    <link name="NeckYaw_link">
        <inertial>
            <mass value="0.51016" />
            <origin xyz="0 0 -0.03074" rpy="0 -0 0" />
            <inertia ixx="0.000739515" ixy="-8.014e-08" ixz="1.145e-08" iyy="0.000764004" iyz="-1.84095e-06" izz="0.000187965" />
        </inertial>
    </link>
    <link name="NeckPitch_link">
        <inertial>
            <mass value="0.23875" />
            <origin xyz="-0.00472 0 0.04432" rpy="0 -0 0" />
            <inertia ixx="0.000397055" ixy="-1.57263e-06" ixz="1.14383e-05" iyy="0.000344" iyz="9.69515e-06" izz="0.0002336" />
        </inertial>
        <visual>
            <origin xyz="0 0 0" rpy="0 -0 0" />
            <geometry>
                <mesh filename="file:///home/sbarthelemy/ar/a/simulation/alrobotmodel/libalmodelutils/share/alrobotmodel/meshes/romeo/NeckPitch.dae" scale="1 1 1" />
            </geometry>
        </visual>
    </link>
    <link name="HeadPitch_link">
        <inertial>
            <mass value="0.13981" />
            <origin xyz="0.00137 0 -0.00641" rpy="0 -0 0" />
            <inertia ixx="3.32156e-05" ixy="-3.814e-08" ixz="-3.52399e-06" iyy="6.65396e-05" iyz="-6.46e-09" izz="5.35026e-05" />
        </inertial>
    </link>
    <link name="HeadRoll_link">
        <inertial>
            <mass value="1.41282" />
            <origin xyz="0.01617 0 0.00757" rpy="0 -0 0" />
            <inertia ixx="0.0148278" ixy="-5.14209e-05" ixz="-0.000511955" iyy="0.0168685" iyz="-0.000191527" izz="0.00698534" />
        </inertial>
        <visual>
            <origin xyz="0 0 0" rpy="0 -0 0" />
            <geometry>
                <mesh filename="file:///home/sbarthelemy/ar/a/simulation/alrobotmodel/libalmodelutils/share/alrobotmodel/meshes/romeo/HeadRoll.dae" scale="1 1 1" />
            </geometry>
        </visual>
        <collision>
            <origin xyz="0.03 0 0.03" rpy="0 -0 0" />
            <geometry>
                <sphere radius="0.12" />
            </geometry>
        </collision>
    </link>
    <link name="TrunkYaw_link">
        <inertial>
            <mass value="4.16277" />
            <origin xyz="0.00932 0 -0.2119" rpy="0 -0 0" />
            <inertia ixx="0.0549643" ixy="-6.88963e-05" ixz="-0.00539193" iyy="0.0508911" iyz="0.000306252" izz="0.0211123" />
        </inertial>
        <visual>
            <origin xyz="0 0 0" rpy="0 -0 0" />
            <geometry>
                <mesh filename="file:///home/sbarthelemy/ar/a/simulation/alrobotmodel/libalmodelutils/share/alrobotmodel/meshes/romeo/TrunkYaw.dae" scale="1 1 1" />
            </geometry>
        </visual>
    </link>
    <link name="base_link" />
    <joint name="AccelerometerHead_fixedjoint" type="fixed">
        <origin xyz="-0.01135 -0.04225 0.16011" rpy="0 -0 1.5708" />
        <axis xyz="0 0 0" />
        <parent link="HeadRoll_link" />
        <child link="AccelerometerHead" />
    </joint>
    <joint name="Head_fixedjoint" type="fixed">
        <origin xyz="0 0 0" rpy="0 -0 0" />
        <axis xyz="0 0 0" />
        <parent link="HeadRoll_link" />
        <child link="Head" />
    </joint>
    <joint name="NeckYaw" type="revolute">
        <origin xyz="0.0048 0 0.0935" rpy="0 -2.98023e-08 0" />
        <axis xyz="0.173651 0 0.984807" />
        <parent link="Torso_link" />
        <child link="NeckYaw_link" />
        <limit effort="3.662" velocity="4" lower="-2.0595" upper="2.0595" />
    </joint>
    <joint name="NeckPitch" type="revolute">
        <origin xyz="0 0 0" rpy="0 -2.98023e-08 0" />
        <axis xyz="0 1 0" />
        <parent link="NeckYaw_link" />
        <child link="NeckPitch_link" />
        <limit effort="2.978" velocity="2.2" lower="-0.3142" upper="0.6632" />
    </joint>
    <joint name="HeadPitch" type="revolute">
        <origin xyz="0 0 0.0951" rpy="0 -0 0" />
        <axis xyz="0 1 0" />
        <parent link="NeckPitch_link" />
        <child link="HeadPitch_link" />
        <limit effort="2.57" velocity="1.9" lower="-0.2571" upper="0.2971" />
    </joint>
    <joint name="HeadRoll" type="revolute">
        <origin xyz="0 0 0" rpy="0 -0 0" />
        <axis xyz="1 0 0" />
        <parent link="HeadPitch_link" />
        <child link="HeadRoll_link" />
        <limit effort="0.9" velocity="1.5" lower="-0.4887" upper="0.4887" />
    </joint>
    <joint name="base_link_fixedjoint" type="fixed">
        <origin xyz="0 0 0" rpy="0 -0 0" />
        <axis xyz="0 0 0" />
        <parent link="base_link" />
        <child link="Torso_link" />
    </joint>
</robot>
